<!--
  GBC486 五连杆轮腿机器人的几何替身版：用 cylinder/box 直接替换原 STL mesh，
  保持与 MJCF/robot.xml 完全相同的 body 树、joint/actuator/sensor/site/equality 名称及位姿，
  使 environment.py / Simulation.py 在不改 Python 代码（仅切换 model_path）的前提下可无缝切换。

  约定：
    - 每节"连杆"用 cylinder（fromto = 本体原点 → 子 body 原点 或对应 site 位置）画出
    - 车身 base_link 用 box；左右轮用 cylinder（沿 body 局部 z 轴）
    - 质量沿用原 mesh 设定（惯量由 MuJoCo 根据 geom 形状 + 质量自动估算）
-->
<mujoco model="GBC486_primitive">
  <default>
    <default class="touch">
        <geom contype="1" conaffinity="1" />
    </default>
    <default class="untouch">
        <geom contype="0" conaffinity="0" />
    </default>
  </default>
  <compiler angle="radian"/>

  <asset>
    <material name="base_mat" rgba="0.2 0.2 0.25 1" specular="0.5" shininess="0.5"/>
    <material name="arm_blue" rgba="0.3 0.5 0.8 1" specular="0.8" shininess="0.8"/>
    <material name="arm_red"  rgba="0.8 0.3 0.3 1" specular="0.8" shininess="0.8"/>
    <material name="joint_mat" rgba="0.7 0.7 0.75 1" specular="1.0" shininess="1.0"/>
    <material name="wheel_mat" rgba="0.15 0.15 0.2 1" specular="0.3" shininess="0.2"/>
  </asset>

  <worldbody>
    <body name="base" pos="0 0 0.2">
    <!-- "扣雷挖及悠打"，注释下面这行代码可以让车身悬浮在空中 -->
      <joint name="base_free" type="free"/>
      <site name="imu" type="box" size="0.002 0.002 0.002" rgba="1 1 0 1"/>
      <!-- 车身：长方体，尺寸取自原 base_link mesh 大致包围盒 -->
      <geom name="base_box" type="box" size="0.12 0.18 0.05" pos="0 0 0.05"
            material="base_mat" class="touch" mass="8.4"/>

      <!-- ============ 右腿臂（蓝色系，rear: AG-GH） ============ -->
      <body name="AG" pos="-0.01375 -0.1995 0.134" quat="0.707105 0.707108 0 0">
        <joint name="jAG" pos="0 0 0" axis="0 0 1" range="-1.57 0.3"/>
        <site name="AG-D" pos="-0.027 -0.094 0" size="0.002" rgba="0 1 0 1"/>
        <geom type="cylinder" fromto="0 0 0  -0.060152 -0.20641 0.0345" size="0.012"
              material="arm_blue" class="untouch" mass="0.667"/>

        <body name="GH" pos="-0.060152 -0.20641 0.0345">
          <joint name="jGH" pos="0 0 0" axis="0 0 1" range="-0.85 1"/>
          <site name="GH-F" pos="-0.0604 0.0259 -0.03" size="0.01" rgba="0 1 0 1"/>
          <site name="GH-little_wheel" pos="-0.033 -0.062 -0.01" size="0.01" rgba="0 1 0 1"/>
          <geom type="cylinder" fromto="0 0 0  0.25495 -0.039583 0.0155" size="0.014"
                material="joint_mat" class="touch" mass="1.64"/>

          <body name="wheel_right" pos="0.25495 -0.039583 0.0155">
            <joint name="jwheel_right" pos="0 0 0" axis="0 0 -1"/>
            <!-- 轮：cylinder 沿 body 局部 z 轴；与 jwheel_right 轴向一致 -->
            <geom type="cylinder" size="0.06 0.018" material="arm_blue"
                  class="touch" mass="0.322"/>
          </body>
        </body>
      </body>

      <!-- ============ 右腿臂（蓝色系，front: AB-BE-EC-CF） ============ -->
      <body name="AB" pos="-0.01375 -0.2155 0.134" quat="0.707105 0.707108 0 0">
        <joint name="jAB" pos="0 0 0" axis="0 0 1" range="-1.57 0.5"/>
        <geom type="cylinder" fromto="0 0 0  0.097866 0.0051238 -0.013" size="0.010"
              material="joint_mat" class="untouch" mass="0.202"/>

        <body name="BE" pos="0.097866 0.0051238 -0.013">
          <joint name="jBE" pos="0 0 0" axis="0 0 1"/>
          <geom type="cylinder" fromto="0 0 0  -0.0090761 -0.11725 0.0094" size="0.008"
                material="arm_blue" class="touch" mass="0.057"/>

          <body name="EC" pos="-0.0090761 -0.11725 0.0094">
            <joint name="jEC" pos="0 0 0" axis="0 0 -1"/>
            <site name="EC-D" pos="-0.115974 0.017382 -0.01" size="0.002" rgba="1 0 0 1"/>
            <geom type="cylinder" fromto="0 0 0  -0.17658 0.044698 -0.0124" size="0.010"
                  material="joint_mat" class="touch" mass="0.128"/>

            <body name="CF" pos="-0.17658 0.044698 -0.0124">
              <joint name="jCF" pos="0 0 0" axis="0 0 -1"/>
              <site name="CF-F" pos="-0.0332 -0.111 0" size="0.002" rgba="1 0 0 1"/>
              <geom type="cylinder" fromto="0 0 0  -0.0332 -0.111 0" size="0.008"
                    material="arm_blue" class="touch" mass="0.057"/>
            </body>
          </body>
        </body>
      </body>

      <!-- ============ 左腿（红色系，front: IJ-JM-MK-KN） ============ -->
      <body name="IJ" pos="-0.01375 0.2165 0.134" quat="0.707105 0.707108 0 0">
        <joint name="jIJ" pos="0 0 0" axis="0 0 -1" range="-0.5 1.57"/>
        <geom type="cylinder" fromto="0 0 0  0.097866 0.0051238 0.013" size="0.010"
              material="joint_mat" class="untouch" mass="0.202"/>

        <body name="JM" pos="0.097866 0.0051238 0.013">
          <joint name="jJM" pos="0 0 0" axis="0 0 -1"/>
          <geom type="cylinder" fromto="0 0 0  -0.0090761 -0.11725 -0.0094" size="0.008"
                material="arm_red" class="touch" mass="0.057"/>

          <body name="MK" pos="-0.0090761 -0.11725 -0.0094">
            <joint name="jMK" pos="0 0 0" axis="0 0 -1"/>
            <site name="MK-L" pos="-0.115974 0.017382 0.01" size="0.01" rgba="1 0 0 1"/>
            <geom type="cylinder" fromto="0 0 0  -0.17658 0.044698 0.0124" size="0.010"
                  material="joint_mat" class="touch" mass="0.128"/>

            <body name="KN" pos="-0.17658 0.044698 0.0124">
              <joint name="jKN" pos="0 0 0" axis="0 0 1"/>
              <site name="KN-N" pos="-0.0332 -0.111 0" size="0.01" rgba="1 0 0 1"/>
              <geom type="cylinder" fromto="0 0 0  -0.0332 -0.111 0" size="0.008"
                    material="arm_red" class="touch" mass="0.057"/>
            </body>
          </body>
        </body>
      </body>

      <!-- ============ 左腿（红色系，rear: IO-OP） ============ -->
      <body name="IO" pos="-0.01375 0.2005 0.134" quat="0.707105 0.707108 0 0">
        <joint name="jIO" pos="0 0 0" axis="0 0 -1" range="-0.3 1.57"/>
        <site name="IO-L" pos="-0.027 -0.094 0" size="0.01" rgba="0 1 0 1"/>
        <geom type="cylinder" fromto="0 0 0  -0.060152 -0.20641 -0.0345" size="0.012"
              material="arm_red" class="untouch" mass="0.667"/>

        <body name="OP" pos="-0.060152 -0.20641 -0.0345">
          <joint name="jOP" pos="0 0 0" axis="0 0 -1" range="-1 0.85"/>
          <site name="OP-N" pos="-0.0604 0.0259 0.03" size="0.01" rgba="0 1 0 1"/>
          <geom type="cylinder" fromto="0 0 0  0.25495 -0.039576 -0.0155" size="0.014"
                material="joint_mat" class="touch" mass="1.64"/>

          <body name="wheel_left" pos="0.25495 -0.039576 -0.0155">
            <joint name="jwheel_left" pos="0 0 0" axis="0 0 1"/>
            <geom type="cylinder" size="0.06 0.018" material="arm_red"
                  class="touch" mass="0.322"/>
          </body>
        </body>
      </body>
    </body>
  </worldbody>

  <equality>
    <connect name="right_D" site1="EC-D" site2="AG-D" solref="0.001 1" solimp="0.99 0.99 0.01 0.5 2"/>
    <connect name="right_F" site1="CF-F" site2="GH-F" solref="0.001 1" solimp="0.99 0.99 0.01 0.5 2"/>
    <connect name="left_L"  site1="IO-L" site2="MK-L" solref="0.001 1" solimp="0.99 0.99 0.01 0.5 2"/>
    <connect name="left_F"  site1="OP-N" site2="KN-N" solref="0.001 1" solimp="0.99 0.99 0.01 0.5 2"/>
  </equality>

  <actuator>
    <general name="Right_front_joint_act" joint="jAB"         gainprm="1"  ctrlrange="-20 +20"/>
    <general name="Right_rear_joint_act"  joint="jAG"         gainprm="1"  ctrlrange="-20 +20"/>
    <general name="Left_front_joint_act"  joint="jIJ"         gainprm="1"  ctrlrange="-20 +20"/>
    <general name="Left_rear_joint_act"   joint="jIO"         gainprm="1"  ctrlrange="-20 +20"/>
    <general name="Right_Wheel_act"       joint="jwheel_right" gainprm="1"  ctrlrange="-4 +4"/>
    <general name="Left_Wheel_act"        joint="jwheel_left"  gainprm="-1" ctrlrange="-4 +4"/>
  </actuator>

  <sensor>
    <framequat name='orientation' objtype='site' objname='imu'/>
    <gyro      name='gyro'        site='imu'/>
    <jointpos joint="jwheel_right" name="Right_Wheel_pos"/>
    <jointpos joint="jwheel_left"  name="Left_Wheel_pos"/>
    <jointpos joint="jAB" name="Right_front_joint_pos"/>
    <jointpos joint="jAG" name="Right_rear_joint_pos"/>
    <jointpos joint="jIJ" name="Left_front_joint_pos"/>
    <jointpos joint="jIO" name="Left_rear_joint_pos"/>
  </sensor>
</mujoco>
